2024-02-10T00:02:02 {"cpu": 0.865234375, "cpu_total": 8, "cpu_usage": 0.108154296875, "memory": 2361.0, "memory_total": 12553.0, "memory_usage": 0.18808253007249262, "pipeline_run_id": 3, "pipeline_schedule_id": 1, "pipeline_uuid": "gcs_to_bigquery", "hostname": "3c82d7250226", "level": "INFO", "message": "Pipeline gcs_to_bigquery for run 3 in schedule 1 is alive.", "timestamp": 1707523322.013228, "uuid": "53f20ffb2a784bd58e2536f19b678a0d"}
2024-02-10T00:02:02 {"cpu": 0.865234375, "cpu_total": 8, "cpu_usage": 0.108154296875, "memory": 2361.0, "memory_total": 12553.0, "memory_usage": 0.18808253007249262, "pipeline_run_id": 3, "pipeline_schedule_id": 1, "pipeline_uuid": "gcs_to_bigquery", "hostname": "3c82d7250226", "level": "INFO", "message": "Pipeline gcs_to_bigquery for run 3 in schedule 1 is alive.", "timestamp": 1707523322.259681, "uuid": "90e66adc816040208d9b5a693c643043"}
2024-02-10T00:02:03 {"block_run_id": 7, "block_uuid": "load_taxi_gcs", "pipeline_run_id": 3, "pipeline_schedule_id": 1, "pipeline_uuid": "gcs_to_bigquery", "hostname": "3c82d7250226", "level": "INFO", "message": "Execute PipelineRun 3, BlockRun 7: pipeline gcs_to_bigquery block load_taxi_gcs", "timestamp": 1707523323.788381, "uuid": "1e6d135f3b7b4b4f9085a5b5dcaf2037"}
2024-02-10T00:02:05 {"block_run_id": 7, "block_uuid": "load_taxi_gcs", "pipeline_run_id": 3, "pipeline_schedule_id": 1, "pipeline_uuid": "gcs_to_bigquery", "hostname": "3c82d7250226", "level": "EXCEPTION", "message": "BlockRun 7 (block_uuid: load_taxi_gcs) failed.", "timestamp": 1707523325.484049, "uuid": "455bf7953d0844f5bb40aed80d37271a", "error": ["Traceback (most recent call last):\n  File \"/usr/local/lib/python3.10/site-packages/mage_ai/data_preparation/executors/block_executor.py\", line 605, in execute\n    result = __execute_with_retry()\n  File \"/usr/local/lib/python3.10/site-packages/mage_ai/shared/retry.py\", line 54, in retry_func\n    raise e\n  File \"/usr/local/lib/python3.10/site-packages/mage_ai/shared/retry.py\", line 38, in retry_func\n    return func(*args, **kwargs)\n  File \"/usr/local/lib/python3.10/site-packages/mage_ai/data_preparation/executors/block_executor.py\", line 578, in __execute_with_retry\n    return self._execute(\n  File \"/usr/local/lib/python3.10/site-packages/mage_ai/data_preparation/executors/block_executor.py\", line 1052, in _execute\n    result = self.block.execute_sync(\n  File \"/usr/local/lib/python3.10/site-packages/mage_ai/data_preparation/models/block/__init__.py\", line 1285, in execute_sync\n    raise err\n  File \"/usr/local/lib/python3.10/site-packages/mage_ai/data_preparation/models/block/__init__.py\", line 1194, in execute_sync\n    output = self.execute_block(\n  File \"/usr/local/lib/python3.10/site-packages/mage_ai/data_preparation/models/block/__init__.py\", line 1509, in execute_block\n    outputs = self._execute_block(\n  File \"/usr/local/lib/python3.10/site-packages/mage_ai/data_preparation/models/block/__init__.py\", line 1665, in _execute_block\n    outputs = self.execute_block_function(\n  File \"/usr/local/lib/python3.10/site-packages/mage_ai/data_preparation/models/block/__init__.py\", line 1704, in execute_block_function\n    output = block_function_updated(*input_vars, **global_vars)\n  File \"<string>\", line 25, in load_from_google_cloud_storage\n  File \"/usr/local/lib/python3.10/site-packages/mage_ai/io/google_cloud_storage.py\", line 95, in load\n    bucket = self.client.get_bucket(bucket_name)\n  File \"/usr/local/lib/python3.10/site-packages/google/cloud/storage/client.py\", line 783, in get_bucket\n    bucket.reload(\n  File \"/usr/local/lib/python3.10/site-packages/google/cloud/storage/bucket.py\", line 1087, in reload\n    super(Bucket, self).reload(\n  File \"/usr/local/lib/python3.10/site-packages/google/cloud/storage/_helpers.py\", line 238, in reload\n    api_response = client._get_resource(\n  File \"/usr/local/lib/python3.10/site-packages/google/cloud/storage/client.py\", line 366, in _get_resource\n    return self._connection.api_request(\n  File \"/usr/local/lib/python3.10/site-packages/google/cloud/storage/_http.py\", line 73, in api_request\n    return call()\n  File \"/usr/local/lib/python3.10/site-packages/google/api_core/retry.py\", line 372, in retry_wrapped_func\n    return retry_target(\n  File \"/usr/local/lib/python3.10/site-packages/google/api_core/retry.py\", line 207, in retry_target\n    result = target()\n  File \"/usr/local/lib/python3.10/site-packages/google/cloud/_http/__init__.py\", line 482, in api_request\n    response = self._make_request(\n  File \"/usr/local/lib/python3.10/site-packages/google/cloud/_http/__init__.py\", line 341, in _make_request\n    return self._do_request(\n  File \"/usr/local/lib/python3.10/site-packages/google/cloud/_http/__init__.py\", line 379, in _do_request\n    return self.http.request(\n  File \"/usr/local/lib/python3.10/site-packages/google/auth/transport/requests.py\", line 537, in request\n    self.credentials.before_request(auth_request, method, url, request_headers)\n  File \"/usr/local/lib/python3.10/site-packages/google/auth/credentials.py\", line 228, in before_request\n    self._blocking_refresh(request)\n  File \"/usr/local/lib/python3.10/site-packages/google/auth/credentials.py\", line 191, in _blocking_refresh\n    self.refresh(request)\n  File \"/usr/local/lib/python3.10/site-packages/google/oauth2/service_account.py\", line 441, in refresh\n    access_token, expiry, _ = _client.jwt_grant(\n  File \"/usr/local/lib/python3.10/site-packages/google/oauth2/_client.py\", line 308, in jwt_grant\n    response_data = _token_endpoint_request(\n  File \"/usr/local/lib/python3.10/site-packages/google/oauth2/_client.py\", line 279, in _token_endpoint_request\n    _handle_error_response(response_data, retryable_error)\n  File \"/usr/local/lib/python3.10/site-packages/google/oauth2/_client.py\", line 72, in _handle_error_response\n    raise exceptions.RefreshError(\ngoogle.auth.exceptions.RefreshError: ('invalid_grant: Invalid JWT: Token must be a short-lived token (60 minutes) and in a reasonable timeframe. Check your iat and exp values in the JWT claim.', {'error': 'invalid_grant', 'error_description': 'Invalid JWT: Token must be a short-lived token (60 minutes) and in a reasonable timeframe. Check your iat and exp values in the JWT claim.'})\n"], "error_stack": [["  File \"/usr/local/bin/mage\", line 8, in <module>\n    sys.exit(app())\n", "  File \"/usr/local/lib/python3.10/site-packages/typer/main.py\", line 311, in __call__\n    return get_command(self)(*args, **kwargs)\n", "  File \"/usr/local/lib/python3.10/site-packages/click/core.py\", line 1130, in __call__\n    return self.main(*args, **kwargs)\n", "  File \"/usr/local/lib/python3.10/site-packages/typer/core.py\", line 778, in main\n    return _main(\n", "  File \"/usr/local/lib/python3.10/site-packages/typer/core.py\", line 216, in _main\n    rv = self.invoke(ctx)\n", "  File \"/usr/local/lib/python3.10/site-packages/click/core.py\", line 1657, in invoke\n    return _process_result(sub_ctx.command.invoke(sub_ctx))\n", "  File \"/usr/local/lib/python3.10/site-packages/click/core.py\", line 1404, in invoke\n    return ctx.invoke(self.callback, **ctx.params)\n", "  File \"/usr/local/lib/python3.10/site-packages/click/core.py\", line 760, in invoke\n    return __callback(*args, **kwargs)\n", "  File \"/usr/local/lib/python3.10/site-packages/typer/main.py\", line 683, in wrapper\n    return callback(**use_params)  # type: ignore\n", "  File \"/usr/local/lib/python3.10/site-packages/mage_ai/cli/main.py\", line 163, in start\n    start_server(\n", "  File \"/usr/local/lib/python3.10/site-packages/mage_ai/server/server.py\", line 659, in start_server\n    scheduler_manager.start_scheduler()\n", "  File \"/usr/local/lib/python3.10/site-packages/mage_ai/server/scheduler_manager.py\", line 87, in start_scheduler\n    proc.start()\n", "  File \"/usr/local/lib/python3.10/multiprocessing/process.py\", line 121, in start\n    self._popen = self._Popen(self)\n", "  File \"/usr/local/lib/python3.10/multiprocessing/context.py\", line 224, in _Popen\n    return _default_context.get_context().Process._Popen(process_obj)\n", "  File \"/usr/local/lib/python3.10/multiprocessing/context.py\", line 281, in _Popen\n    return Popen(process_obj)\n", "  File \"/usr/local/lib/python3.10/multiprocessing/popen_fork.py\", line 19, in __init__\n    self._launch(process_obj)\n", "  File \"/usr/local/lib/python3.10/multiprocessing/popen_fork.py\", line 71, in _launch\n    code = process_obj._bootstrap(parent_sentinel=child_r)\n", "  File \"/usr/local/lib/python3.10/multiprocessing/process.py\", line 314, in _bootstrap\n    self.run()\n", "  File \"/usr/local/lib/python3.10/multiprocessing/process.py\", line 108, in run\n    self._target(*self._args, **self._kwargs)\n", "  File \"/usr/local/lib/python3.10/site-packages/mage_ai/orchestration/db/process.py\", line 15, in start_session_and_run\n    results = target(*args)\n", "  File \"/usr/local/lib/python3.10/site-packages/mage_ai/server/scheduler_manager.py\", line 50, in run_scheduler\n    LoopTimeTrigger().start()\n", "  File \"/usr/local/lib/python3.10/site-packages/mage_ai/orchestration/triggers/loop_time_trigger.py\", line 14, in start\n    self.run()\n", "  File \"/usr/local/lib/python3.10/site-packages/mage_ai/orchestration/triggers/time_trigger.py\", line 11, in run\n    schedule_all()\n", "  File \"/usr/local/lib/python3.10/site-packages/mage_ai/orchestration/pipeline_scheduler_original.py\", line 1552, in schedule_all\n    PipelineScheduler(r).start()\n", "  File \"/usr/local/lib/python3.10/site-packages/mage_ai/orchestration/db/__init__.py\", line 149, in func_with_rollback\n    return func(*args, **kwargs)\n", "  File \"/usr/local/lib/python3.10/site-packages/mage_ai/orchestration/pipeline_scheduler_original.py\", line 182, in start\n    self.schedule()\n", "  File \"/usr/local/lib/python3.10/site-packages/mage_ai/orchestration/db/__init__.py\", line 149, in func_with_rollback\n    return func(*args, **kwargs)\n", "  File \"/usr/local/lib/python3.10/site-packages/mage_ai/orchestration/pipeline_scheduler_original.py\", line 319, in schedule\n    self.__schedule_blocks(block_runs)\n", "  File \"/usr/local/lib/python3.10/site-packages/mage_ai/orchestration/pipeline_scheduler_original.py\", line 581, in __schedule_blocks\n    job_manager.add_job(\n", "  File \"/usr/local/lib/python3.10/site-packages/mage_ai/orchestration/job_manager.py\", line 27, in add_job\n    self.queue.enqueue(job_id, target, *args, **kwargs)\n", "  File \"/usr/local/lib/python3.10/site-packages/mage_ai/orchestration/queue/process_queue.py\", line 107, in enqueue\n    self.start_worker_pool()\n", "  File \"/usr/local/lib/python3.10/site-packages/mage_ai/orchestration/queue/process_queue.py\", line 173, in start_worker_pool\n    self.worker_pool_proc.start()\n", "  File \"/usr/local/lib/python3.10/multiprocessing/process.py\", line 121, in start\n    self._popen = self._Popen(self)\n", "  File \"/usr/local/lib/python3.10/multiprocessing/context.py\", line 224, in _Popen\n    return _default_context.get_context().Process._Popen(process_obj)\n", "  File \"/usr/local/lib/python3.10/multiprocessing/context.py\", line 281, in _Popen\n    return Popen(process_obj)\n", "  File \"/usr/local/lib/python3.10/multiprocessing/popen_fork.py\", line 19, in __init__\n    self._launch(process_obj)\n", "  File \"/usr/local/lib/python3.10/multiprocessing/popen_fork.py\", line 71, in _launch\n    code = process_obj._bootstrap(parent_sentinel=child_r)\n", "  File \"/usr/local/lib/python3.10/multiprocessing/process.py\", line 314, in _bootstrap\n    self.run()\n", "  File \"/usr/local/lib/python3.10/multiprocessing/process.py\", line 108, in run\n    self._target(*self._args, **self._kwargs)\n", "  File \"/usr/local/lib/python3.10/site-packages/mage_ai/orchestration/queue/process_queue.py\", line 275, in poll_job_and_execute\n    worker.start()\n", "  File \"/usr/local/lib/python3.10/multiprocessing/process.py\", line 121, in start\n    self._popen = self._Popen(self)\n", "  File \"/usr/local/lib/python3.10/multiprocessing/context.py\", line 224, in _Popen\n    return _default_context.get_context().Process._Popen(process_obj)\n", "  File \"/usr/local/lib/python3.10/multiprocessing/context.py\", line 281, in _Popen\n    return Popen(process_obj)\n", "  File \"/usr/local/lib/python3.10/multiprocessing/popen_fork.py\", line 19, in __init__\n    self._launch(process_obj)\n", "  File \"/usr/local/lib/python3.10/multiprocessing/popen_fork.py\", line 71, in _launch\n    code = process_obj._bootstrap(parent_sentinel=child_r)\n", "  File \"/usr/local/lib/python3.10/multiprocessing/process.py\", line 314, in _bootstrap\n    self.run()\n", "  File \"/usr/local/lib/python3.10/site-packages/newrelic/api/background_task.py\", line 117, in wrapper\n    return wrapped(*args, **kwargs)\n", "  File \"/usr/local/lib/python3.10/site-packages/mage_ai/orchestration/queue/process_queue.py\", line 240, in run\n    start_session_and_run(args[1], *args[2], **args[3])\n", "  File \"/usr/local/lib/python3.10/site-packages/mage_ai/orchestration/db/process.py\", line 15, in start_session_and_run\n    results = target(*args)\n", "  File \"/usr/local/lib/python3.10/site-packages/mage_ai/orchestration/pipeline_scheduler_original.py\", line 1105, in run_block\n    return ExecutorFactory.get_block_executor(\n", "  File \"/usr/local/lib/python3.10/site-packages/mage_ai/data_preparation/executors/block_executor.py\", line 621, in execute\n    on_failure(\n", "  File \"/usr/local/lib/python3.10/site-packages/mage_ai/orchestration/db/__init__.py\", line 149, in func_with_rollback\n    return func(*args, **kwargs)\n", "  File \"/usr/local/lib/python3.10/site-packages/mage_ai/orchestration/pipeline_scheduler_original.py\", line 415, in on_block_failure\n    self.logger.exception(\n", "  File \"/usr/local/lib/python3.10/site-packages/mage_ai/data_preparation/logging/logger.py\", line 30, in exception\n    self.__send_message('exception', message, **kwargs)\n", "  File \"/usr/local/lib/python3.10/site-packages/mage_ai/data_preparation/logging/logger.py\", line 59, in __send_message\n    data['error_stack'] = traceback.format_stack(),\n"]], "error_stacktrace": ["('invalid_grant: Invalid JWT: Token must be a short-lived token (60 minutes) and in a reasonable timeframe. Check your iat and exp values in the JWT claim.', {'error': 'invalid_grant', 'error_description': 'Invalid JWT: Token must be a short-lived token (60 minutes) and in a reasonable timeframe. Check your iat and exp values in the JWT claim.'})"]}
Traceback (most recent call last):
  File "/usr/local/lib/python3.10/site-packages/mage_ai/data_preparation/executors/block_executor.py", line 605, in execute
    result = __execute_with_retry()
  File "/usr/local/lib/python3.10/site-packages/mage_ai/shared/retry.py", line 54, in retry_func
    raise e
  File "/usr/local/lib/python3.10/site-packages/mage_ai/shared/retry.py", line 38, in retry_func
    return func(*args, **kwargs)
  File "/usr/local/lib/python3.10/site-packages/mage_ai/data_preparation/executors/block_executor.py", line 578, in __execute_with_retry
    return self._execute(
  File "/usr/local/lib/python3.10/site-packages/mage_ai/data_preparation/executors/block_executor.py", line 1052, in _execute
    result = self.block.execute_sync(
  File "/usr/local/lib/python3.10/site-packages/mage_ai/data_preparation/models/block/__init__.py", line 1285, in execute_sync
    raise err
  File "/usr/local/lib/python3.10/site-packages/mage_ai/data_preparation/models/block/__init__.py", line 1194, in execute_sync
    output = self.execute_block(
  File "/usr/local/lib/python3.10/site-packages/mage_ai/data_preparation/models/block/__init__.py", line 1509, in execute_block
    outputs = self._execute_block(
  File "/usr/local/lib/python3.10/site-packages/mage_ai/data_preparation/models/block/__init__.py", line 1665, in _execute_block
    outputs = self.execute_block_function(
  File "/usr/local/lib/python3.10/site-packages/mage_ai/data_preparation/models/block/__init__.py", line 1704, in execute_block_function
    output = block_function_updated(*input_vars, **global_vars)
  File "<string>", line 25, in load_from_google_cloud_storage
  File "/usr/local/lib/python3.10/site-packages/mage_ai/io/google_cloud_storage.py", line 95, in load
    bucket = self.client.get_bucket(bucket_name)
  File "/usr/local/lib/python3.10/site-packages/google/cloud/storage/client.py", line 783, in get_bucket
    bucket.reload(
  File "/usr/local/lib/python3.10/site-packages/google/cloud/storage/bucket.py", line 1087, in reload
    super(Bucket, self).reload(
  File "/usr/local/lib/python3.10/site-packages/google/cloud/storage/_helpers.py", line 238, in reload
    api_response = client._get_resource(
  File "/usr/local/lib/python3.10/site-packages/google/cloud/storage/client.py", line 366, in _get_resource
    return self._connection.api_request(
  File "/usr/local/lib/python3.10/site-packages/google/cloud/storage/_http.py", line 73, in api_request
    return call()
  File "/usr/local/lib/python3.10/site-packages/google/api_core/retry.py", line 372, in retry_wrapped_func
    return retry_target(
  File "/usr/local/lib/python3.10/site-packages/google/api_core/retry.py", line 207, in retry_target
    result = target()
  File "/usr/local/lib/python3.10/site-packages/google/cloud/_http/__init__.py", line 482, in api_request
    response = self._make_request(
  File "/usr/local/lib/python3.10/site-packages/google/cloud/_http/__init__.py", line 341, in _make_request
    return self._do_request(
  File "/usr/local/lib/python3.10/site-packages/google/cloud/_http/__init__.py", line 379, in _do_request
    return self.http.request(
  File "/usr/local/lib/python3.10/site-packages/google/auth/transport/requests.py", line 537, in request
    self.credentials.before_request(auth_request, method, url, request_headers)
  File "/usr/local/lib/python3.10/site-packages/google/auth/credentials.py", line 228, in before_request
    self._blocking_refresh(request)
  File "/usr/local/lib/python3.10/site-packages/google/auth/credentials.py", line 191, in _blocking_refresh
    self.refresh(request)
  File "/usr/local/lib/python3.10/site-packages/google/oauth2/service_account.py", line 441, in refresh
    access_token, expiry, _ = _client.jwt_grant(
  File "/usr/local/lib/python3.10/site-packages/google/oauth2/_client.py", line 308, in jwt_grant
    response_data = _token_endpoint_request(
  File "/usr/local/lib/python3.10/site-packages/google/oauth2/_client.py", line 279, in _token_endpoint_request
    _handle_error_response(response_data, retryable_error)
  File "/usr/local/lib/python3.10/site-packages/google/oauth2/_client.py", line 72, in _handle_error_response
    raise exceptions.RefreshError(
google.auth.exceptions.RefreshError: ('invalid_grant: Invalid JWT: Token must be a short-lived token (60 minutes) and in a reasonable timeframe. Check your iat and exp values in the JWT claim.', {'error': 'invalid_grant', 'error_description': 'Invalid JWT: Token must be a short-lived token (60 minutes) and in a reasonable timeframe. Check your iat and exp values in the JWT claim.'})
2024-02-10T00:02:10 {"cpu": 0.8603515625, "cpu_total": 8, "cpu_usage": 0.1075439453125, "memory": 2387.0, "memory_total": 12553.0, "memory_usage": 0.190153748108022, "pipeline_run_id": 3, "pipeline_schedule_id": 1, "pipeline_uuid": "gcs_to_bigquery", "hostname": "3c82d7250226", "level": "INFO", "message": "Pipeline gcs_to_bigquery for run 3 in schedule 1 is alive.", "timestamp": 1707523330.48258, "uuid": "29139af560744d92a373e6018468c835"}
